<?xml version="1.0"?>
<robot xmlns:xacro="http://www.ros.org/wiki/xacro">
    <xacro:include filename="$(find firstrobot_description)/urdf/fishbot/common_inertia.xacro"/>
    <xacro:macro name="wheel_xacro" params="wheel_name xyz">
        <link name="${wheel_name}_wheel_link">
            <visual>
                <!-- 沿几何中心的偏移量 -->
                <origin xyz="0.0 0.0 0.0" rpy="1.57079 0.0 0.0"/>
                <geometry>
                    <!-- 圆柱半径和高度 -->
                    <cylinder radius="0.032" length="0.04"/>
                </geometry>
                <material name="yellow">
                    <color rgba="1.0 1.0 0.0 0.5"/>
                </material>
            </visual>
            <collision>
                <!-- 沿几何中心的偏移量 -->
                <origin xyz="0.0 0.0 0.0" rpy="1.57079 0.0 0.0"/>
                <geometry>
                    <!-- 圆柱半径和高度 -->
                    <cylinder radius="0.032" length="0.04"/>
                </geometry>
                <material name="yellow">
                    <color rgba="1.0 1.0 0.0 0.5"/>
                </material>
            </collision>
            <xacro:cylinder_inertia m="0.05" r="0.04" h="0.032"/>
        </link>

        <joint name="${wheel_name}_wheel_joint" type="continuous">
            <parent link="base_link"/>                                                                                                               
            <child link="${wheel_name}_wheel_link"/>
            <origin xyz="${xyz}" rpy="0.0 0.0 0.0"/>    
            <axis xyz="0.0 1 0.0"/>
        </joint>

        <gazebo reference="${wheel_name}_wheel_link">
            <mu1 value="20.0"/>
            <mu2 value="20.0"/>
            <kp value="1000000000"/>
            <kd value="1.0"/>
        </gazebo>
    </xacro:macro>
    
</robot>